<?xml version="1.0"?>
<robot name="full_robot">
  <link name="base_link">
    <visual>
      <geometry>
        <box size="0.5 0.5 0.1" />
      </geometry>
      <material name="grey">
        <color rgba="0.7 0.7 0.7 1.0" />
      </material>
    </visual>
  </link>
  <link name="arm_link">
    <visual>
      <geometry>
        <cylinder length="0.6" radius="0.05" />
      </geometry>
      <origin xyz="0 0 0.3" rpy="0 0 0" />
      <material name="blue">
        <color rgba="0.1 0.3 0.8 1.0" />
      </material>
    </visual>
  </link>
  <joint name="base_to_arm" type="revolute">
    <parent link="base_link" />
    <child link="arm_link" />
    <origin xyz="0 0 0.05" rpy="0 0 0" />
    <axis xyz="0 0 1" />
    <limit effort="5.0" lower="-3.14" upper="3.14" velocity="1.0" />
  </joint>
</robot>
